import asyncio
from unittest.mock import AsyncMock, call, patch

import pytest

from jobbers.models.task import Task, TaskStatus
from jobbers.registry import TaskConfig
from jobbers.state_manager import StateManager
from jobbers.task_processor import TaskProcessor


@pytest.mark.asyncio
async def test_task_processor_success():
    """Test that TaskProcessor successfully processes a task."""
    task = Task(
        id="01JQC31AJP7TSA9X8AEP64XG08",
        name="test_task",
        version=1,
        parameters={"param1": "value1"},
        status=TaskStatus.SUBMITTED,
        queue="test_queue",
    )
    state_manager = AsyncMock(spec=StateManager)
    task_function = AsyncMock(return_value={"result": "success"})

    task_config = TaskConfig(
        name="test_task",
        version=1,
        function=task_function,
        timeout=10,
        max_retries=3,
    )

    with patch("jobbers.task_processor.get_task_config", return_value=task_config):
        processor = TaskProcessor(state_manager)
        result_task = await processor.process(task)

    assert result_task.status == TaskStatus.COMPLETED
    assert result_task.results == {"result": "success"}
    # Once when starting and once when done
    state_manager.submit_task.assert_has_calls([call(result_task), call(result_task)])


@pytest.mark.asyncio
async def test_task_processor_dropped_task():
    """Test that TaskProcessor handles a dropped task."""
    task = Task(
        id="01JQC31AJP7TSA9X8AEP64XG08",
        name="unknown_task",
        version=1,
        status=TaskStatus.UNSUBMITTED,
    )
    state_manager = AsyncMock(spec=StateManager)

    with patch("jobbers.task_processor.get_task_config", return_value=None):
        processor = TaskProcessor(state_manager)
        result_task = await processor.process(task)

    assert result_task.status == TaskStatus.DROPPED
    assert result_task.completed_at is not None
    # Once when starting
    state_manager.submit_task.assert_called_once_with(result_task)



@pytest.mark.asyncio
async def test_task_processor_expected_exception():
    """Test that TaskProcessor handles an expected exception."""
    task = Task(
        id="01JQC31AJP7TSA9X8AEP64XG08",
        name="test_task",
        version=1,
        parameters={"param1": "value1"},
        status=TaskStatus.UNSUBMITTED,
        retry_attempt=0,
    )
    state_manager = AsyncMock(spec=StateManager)
    task_function = AsyncMock(side_effect=ValueError("Expected error"))
    task_config = TaskConfig(
        name="test_task",
        version=1,
        function=task_function,
        timeout=10,
        max_retries=3,
        expected_exceptions=(ValueError,),  # Specify expected exceptions for retry logic
    )

    with patch("jobbers.task_processor.get_task_config", return_value=task_config):
        processor = TaskProcessor(state_manager)
        result_task = await processor.process(task)

    assert result_task.status == TaskStatus.UNSUBMITTED
    assert result_task.retry_attempt == 1
    assert "Expected error" in result_task.error
    # Once when starting and once when done
    state_manager.submit_task.assert_has_calls([call(result_task), call(result_task)])



@pytest.mark.asyncio
async def test_task_processor_unexpected_exception():
    """Test that TaskProcessor handles an unexpected exception."""
    task = Task(
        id="01JQC31AJP7TSA9X8AEP64XG08",
        name="test_task",
        version=1,
        parameters={"param1": "value1"},
        status=TaskStatus.UNSUBMITTED,
    )
    state_manager = AsyncMock(spec=StateManager)
    task_function = AsyncMock(side_effect=RuntimeError("Unexpected error"))
    task_config = TaskConfig(
        name="test_task",
        version=1,
        function=task_function,
        timeout=10,
        max_retries=3,
        expected_exceptions=(ValueError,),  # Specify expected exceptions for retry logic
    )

    with patch("jobbers.task_processor.get_task_config", return_value=task_config):
        processor = TaskProcessor(state_manager)
        result_task = await processor.process(task)

    assert result_task.status == TaskStatus.FAILED
    assert "Unexpected error" in result_task.error
    # Once when starting and once when done
    state_manager.submit_task.assert_has_calls([call(result_task), call(result_task)])



@pytest.mark.asyncio
async def test_task_processor_timeout_with_retry():
    """Test that TaskProcessor handles a timeout exception."""
    task = Task(
        id="01JQC31AJP7TSA9X8AEP64XG08",
        name="test_task",
        version=1,
        parameters={"param1": "value1"},
        status=TaskStatus.SUBMITTED,
    )
    state_manager = AsyncMock(spec=StateManager)
    task_function = AsyncMock(side_effect=asyncio.TimeoutError)
    task_config = TaskConfig(
        name="test_task",
        version=1,
        function=task_function,
        timeout=1,
        max_retries=3,
    )

    with patch("jobbers.task_processor.get_task_config", return_value=task_config):
        processor = TaskProcessor(state_manager)
        result_task = await processor.process(task)

    assert result_task.status == TaskStatus.UNSUBMITTED
    assert "timed out" in result_task.error
    # Once when starting and once when done
    state_manager.submit_task.assert_has_calls([call(result_task), call(result_task)])


@pytest.mark.asyncio
async def test_task_processor_timeout_without_retry():
    """Test that TaskProcessor handles a timeout exception."""
    task = Task(
        id="01JQC31AJP7TSA9X8AEP64XG08",
        name="test_task",
        version=1,
        parameters={"param1": "value1"},
        status=TaskStatus.SUBMITTED,
    )
    state_manager = AsyncMock(spec=StateManager)
    task_function = AsyncMock(side_effect=asyncio.TimeoutError)
    task_config = TaskConfig(
        name="test_task",
        version=1,
        function=task_function,
        timeout=1,
        max_retries=0,  # No retries for this task
    )

    with patch("jobbers.task_processor.get_task_config", return_value=task_config):
        processor = TaskProcessor(state_manager)
        result_task = await processor.process(task)

    assert result_task.status == TaskStatus.FAILED
    assert result_task.completed_at is not None, "Failed tasks should have a completed_at timestamp"
    assert "timed out" in result_task.error
    # Once when starting and once when done
    state_manager.submit_task.assert_has_calls([call(result_task), call(result_task)])


@pytest.mark.asyncio
async def test_task_processor_cancelled():
    """Test that TaskProcessor handles a timeout exception."""
    task = Task(
        id="01JQC31AJP7TSA9X8AEP64XG08",
        name="test_task",
        version=1,
        parameters={"param1": "value1"},
        status=TaskStatus.SUBMITTED,
    )
    state_manager = AsyncMock(spec=StateManager)
    task_function = AsyncMock(side_effect=asyncio.CancelledError)
    task_config = TaskConfig(
        name="test_task",
        version=1,
        function=task_function,
        timeout=1,
        max_retries=0,  # No retries for this task
    )

    with patch("jobbers.task_processor.get_task_config", return_value=task_config):
        processor = TaskProcessor(state_manager)
        with pytest.raises(asyncio.CancelledError):
            await processor.process(task)

    # the task should have been updated via side effects
    assert task.status == TaskStatus.CANCELLED
    assert task.completed_at is not None, "Cancelled tasks should have a completed_at timestamp"
    # Once when starting and once when done
    state_manager.submit_task.assert_has_calls([call(task), call(task)])

